Workbook

Sheet Data_overview
A2: year → numeric, model year of the car
A3: make → text, brand name
A4: model → text, car model
A5: trim → text, version of the model
A6: body → text, body type (SUV, Sedan, etc.)
A7: transmission → text
A8: vin → text, unique id
A9: state → text, location
A10: condition → numeric score
A11: odometer → numeric, mileage
A12: color → text
A13: interior → text
... A17: saledate → text → converted to sale_year

Sheet Data_quality_check
A1: sellingprice | E1: condition | I1: odometer
A2: Count | B2: =COUNT(Table1[sellingprice]) -> 1999 | E2: Count | F2: =COUNT(Table1[condition]) -> 1944 | I2: Count | J2: =COUNT((Table1[odometer])) -> 1999
A3: Average | B3: =AVERAGE(Table1[sellingprice]) -> 20393.274 | E3: Average | F3: =AVERAGE((Table1[condition])) -> 33.529321 | I3: Average | J3: =AVERAGE((Table1[odometer])) -> 35371.082
A4: Median | B4: =MEDIAN(Table1[sellingprice]) -> 18200 | E4: Median | F4: =MEDIAN((Table1[condition])) -> 38 | I4: Median | J4: =MEDIAN((Table1[odometer])) -> 32906
A5: Std Dev | B5: =_xlfn.STDEV.S((Table1[sellingprice])) -> 11708.734 | E5: Std Dev | F5: =_xlfn.STDEV.S((Table1[condition])) -> 13.332177 | I5: Std Dev | J5: =_xlfn.STDEV.S((Table1[odometer])) -> 29372.755
A6: Min | B6: =_xlfn.QUARTILE.INC((Table1[sellingprice]), C6) -> 1000 | C6: 0 | D6: =VLOOKUP(B6, car_sale_raw_dataset!O:R, 4, FALSE) -> Nissan Maxima 3.5 S | E6: Min | F6: =_xlfn.QUARTILE.INC((Table1[condition]), G6) -> 1 | G6: 0 | H6: =VLOOKUP(F6, car_sale_raw_dataset!$I:$R, 10, FALSE) -> Nissan Altima 2.5 S | I6: Min | J6: =_xlfn.QUARTILE.INC((Table1[odometer]), K6) -> 1 | K6: 0 | L6: =VLOOKUP(J6, car_sale_raw_dataset!$J:$R, 9, FALSE) -> Nissan Maxima 3.5 S
A7: 1st Quartile | B7: =_xlfn.QUARTILE.INC((Table1[sellingprice]), C7) -> 12100 | C7: 1 | E7: 1st Quartile | F7: =_xlfn.QUARTILE.INC((Table1[condition]), G7) -> 29 | G7: 1 | I7: 1st Quartile | J7: =_xlfn.QUARTILE.INC((Table1[odometer]), K7) -> 21323 | K7: 1
A8: 2nd Quartile | B8: =_xlfn.QUARTILE.INC((Table1[sellingprice]), C8) -> 18200 | C8: 2 | E8: 2nd Quartile | F8: =_xlfn.QUARTILE.INC((Table1[condition]), G8) -> 38 | G8: 2 | I8: 2nd Quartile | J8: =_xlfn.QUARTILE.INC((Table1[odometer]), K8) -> 32906 | K8: 2
A9: 3rd Quartile | B9: =_xlfn.QUARTILE.INC((Table1[sellingprice]), C9) -> 25000 | C9: 3 | E9: 3rd Quartile | F9: =_xlfn.QUARTILE.INC((Table1[condition]), G9) -> 43 | G9: 3 | I9: 3rd Quartile | J9: =_xlfn.QUARTILE.INC((Table1[odometer]), K9) -> 43261 | K9: 3
A10: Max | B10: =_xlfn.QUARTILE.INC((Table1[sellingprice]), C10) -> 154000 | C10: 4 | D10: =VLOOKUP(B10, car_sale_raw_dataset!O:R, 4, FALSE) -> Ferrari California Base | E10: Max | F10: =_xlfn.QUARTILE.INC((Table1[condition]), G10) -> 49 | G10: 4 | H10: =VLOOKUP(F10, car_sale_raw_dataset!$I:$R, 10, FALSE) -> Audi Q5 2.0T Premium Plus quattro | I10: Max | J10: =_xlfn.QUARTILE.INC((Table1[odometer]), K10) -> 999999 | K10: 4 | L10: =VLOOKUP(J10, car_sale_raw_dataset!$J:$R, 9, FALSE) -> Hyundai Elantra Coupe GS
A11: Mode | B11: =MODE((Table1[sellingprice])) -> 21000 | E11: Mode | F11: =MODE((Table1[condition])) -> 44 | I11: Mode | J11: =MODE((Table1[odometer])) -> 13661

Sheet Top5_Count_make_model_trim_body
A3: Row Labels | B3: Count of make | E3: Row Labels | F3: Count of model | I3: Row Labels | J3: Count of trim
A4: BMW | B4: 330 | E4: 3 Series | F4: 151 | I4: 328i | J4: 109
A5: Ford | B5: 137 | E5: Altima | F5: 118 | I5: Base | J5: 173
A6: Hyundai | B6: 189 | E6: Elantra | F6: 53 | I6: G37 Journey | J6: 139
A7: Infiniti | B7: 249 | E7: G Sedan | F7: 181 | I7: GLS | J7: 86
A8: Nissan | B8: 244 | E8: Sonata | F8: 54 | I8: SE | J8: 88
A9: Grand Total | B9: 1149 | E9: Grand Total | F9: 557 | I9: Grand Total | J9: 595
A12: Row Labels | B12: Count of body
A13: Convertible | B13: 103
A14: G Sedan | B14: 181
A15: Hatchback | B15: 145
A16: Sedan | B16: 961
A17: SUV | B17: 320
A18: Grand Total | B18: 1710

Sheet car_sale_raw_dataset
A1: year | B1: make | C1: model | D1: trim | E1: body | F1: transmission | G1: vin | H1: state | I1: condition | J1: odometer | K1: color | L1: interior | M1: seller | N1: mmr | O1: sellingprice | P1: saledate | Q1: sale_year | R1: car_full_name | S1: condition_flag | T1: price_flag
A2: 2015 | B2: Kia | C2: Sorento | D2: LX | E2: SUV | F2: automatic | G2: 5xyktca69fg566472 | H2: ca | I2: 5 | J2: 16639 | K2: white | L2: black | M2: kia motors america inc | N2: 20500 | O2: 21500 | P2: Tue Dec 16 2014 12:30:00 GMT-0800 (PST) | Q2: {=VALUE(INDEX(_xlfn.TEXTSPLIT(P2, " "), 4))} -> 2014 | R2: =_xlfn.TEXTJOIN(" ", TRUE, B2, C2, D2) -> Kia Sorento LX | S2: {=_xlfn.IFS(I2 >= 40, "High", I2>=20, "Medium", I2<20, "Low")} -> Low | T2: {=_xlfn.IFS(O2<18200, "Low", O2<=50000, "Medium", O2>50000, "High")} -> Medium | W2: Min | X2: =MIN(O:O) -> 1000
A3: 2015 | B3: Kia | C3: Sorento | D3: LX | E3: SUV | F3: automatic | G3: 5xyktca69fg561319 | H3: ca | I3: 5 | J3: 9393 | K3: white | L3: beige | M3: kia motors america inc | N3: 20800 | O3: 21500 | P3: Tue Dec 16 2014 12:30:00 GMT-0800 (PST) | Q3: {=VALUE(INDEX(_xlfn.TEXTSPLIT(P3, " "), 4))} -> 2014 | R3: =_xlfn.TEXTJOIN(" ", TRUE, B3, C3, D3) -> Kia Sorento LX | S3: {=_xlfn.IFS(I3 >= 40, "High", I3>=20, "Medium", I3<20, "Low")} -> Low | T3: {=_xlfn.IFS(O3<18200, "Low", O3<=50000, "Medium", O3>50000, "High")} -> Medium | W3: Median | X3: =MEDIAN(O:O) -> 18200
A4: 2014 | B4: BMW | C4: 3 Series | D4: 328i SULEV | E4: Sedan | F4: automatic | G4: wba3c1c51ek116351 | H4: ca | I4: 45 | J4: 1331 | K4: gray | L4: black | M4: financial services remarketing (lease) | N4: 31900 | O4: 30000 | P4: Thu Jan 15 2015 04:30:00 GMT-0800 (PST) | Q4: {=VALUE(INDEX(_xlfn.TEXTSPLIT(P4, " "), 4))} -> 2015 | R4: =_xlfn.TEXTJOIN(" ", TRUE, B4, C4, D4) -> BMW 3 Series 328i SULEV | S4: {=_xlfn.IFS(I4 >= 40, "High", I4>=20, "Medium", I4<20, "Low")} -> High | T4: {=_xlfn.IFS(O4<18200, "Low", O4<=50000, "Medium", O4>50000, "High")} -> Medium | W4: Max | X4: =MAX(O:O) -> 154000
A5: 2015 | B5: Volvo | C5: S60 | D5: T5 | E5: Sedan | F5: automatic | G5: yv1612tb4f1310987 | H5: ca | I5: 41 | J5: 14282 | K5: white | L5: black | M5: volvo na rep/world omni | N5: 27500 | O5: 27750 | P5: Thu Jan 29 2015 04:30:00 GMT-0800 (PST) | Q5: {=VALUE(INDEX(_xlfn.TEXTSPLIT(P5, " "), 4))} -> 2015 | R5: =_xlfn.TEXTJOIN(" ", TRUE, B5, C5, D5) -> Volvo S60 T5 | S5: {=_xlfn.IFS(I5 >= 40, "High", I5>=20, "Medium", I5<20, "Low")} -> High | T5: {=_xlfn.IFS(O5<18200, "Low", O5<=50000, "Medium", O5>50000, "High")} -> Medium
A6: 2014 | B6: BMW | C6: 6 Series Gran Coupe | D6: 650i | E6: Sedan | F6: automatic | G6: wba6b2c57ed129731 | H6: ca | I6: 43 | J6: 2641 | K6: gray | L6: black | M6: financial services remarketing (lease) | N6: 66000 | O6: 67000 | P6: Thu Dec 18 2014 12:30:00 GMT-0800 (PST) | Q6: {=VALUE(INDEX(_xlfn.TEXTSPLIT(P6, " "), 4))} -> 2014 | R6: =_xlfn.TEXTJOIN(" ", TRUE, B6, C6, D6) -> BMW 6 Series Gran Coupe 650i | S6: {=_xlfn.IFS(I6 >= 40, "High", I6>=20, "Medium", I6<20, "Low")} -> High | T6: {=_xlfn.IFS(O6<18200, "Low", O6<=50000, "Medium", O6>50000, "High")} -> High
A7: 2015 | B7: Nissan | C7: Altima | D7: 2.5 S | E7: Sedan | F7: automatic | G7: 1n4al3ap1fn326013 | H7: ca | I7: 1 | J7: 5554 | K7: gray | L7: black | M7: enterprise vehicle exchange / tra / rental / tulsa | N7: 15350 | O7: 10900 | P7: Tue Dec 30 2014 12:00:00 GMT-0800 (PST) | Q7: {=VALUE(INDEX(_xlfn.TEXTSPLIT(P7, " "), 4))} -> 2014 | R7: =_xlfn.TEXTJOIN(" ", TRUE, B7, C7, D7) -> Nissan Altima 2.5 S | S7: {=_xlfn.IFS(I7 >= 40, "High", I7>=20, "Medium", I7<20, "Low")} -> Low | T7: {=_xlfn.IFS(O7<18200, "Low", O7<=50000, "Medium", O7>50000, "High")} -> Low
A8: 2014 | B8: BMW | C8: M5 | D8: Base | E8: Sedan | F8: automatic | G8: wbsfv9c51ed593089 | H8: ca | I8: 34 | J8: 14943 | K8: black | L8: black | M8: the hertz corporation | N8: 69000 | O8: 65000 | P8: Wed Dec 17 2014 12:30:00 GMT-0800 (PST) | Q8: {=VALUE(INDEX(_xlfn.TEXTSPLIT(P8, " "), 4))} -> 2014 | R8: =_xlfn.TEXTJOIN(" ", TRUE, B8, C8, D8) -> BMW M5 Base | S8: {=_xlfn.IFS(I8 >= 40, "High", I8>=20, "Medium", I8<20, "Low")} -> Medium | T8: {=_xlfn.IFS(O8<18200, "Low", O8<=50000, "Medium", O8>50000, "High")} -> High | W8: =FIND(1, J:J) -> 1
A9: 2014 | B9: Chevrolet | C9: Cruze | D9: 1LT | E9: Sedan | F9: automatic | G9: 1g1pc5sb2e7128460 | H9: ca | I9: 2 | J9: 28617 | K9: black | L9: black | M9: enterprise vehicle exchange / tra / rental / tulsa | N9: 11900 | O9: 9800 | P9: Tue Dec 16 2014 13:00:00 GMT-0800 (PST) | Q9: {=VALUE(INDEX(_xlfn.TEXTSPLIT(P9, " "), 4))} -> 2014 | R9: =_xlfn.TEXTJOIN(" ", TRUE, B9, C9, D9) -> Chevrolet Cruze 1LT | S9: {=_xlfn.IFS(I9 >= 40, "High", I9>=20, "Medium", I9<20, "Low")} -> Low | T9: {=_xlfn.IFS(O9<18200, "Low", O9<=50000, "Medium", O9>50000, "High")} -> Low
A10: 2014 | B10: Audi | C10: A4 | D10: 2.0T Premium Plus quattro | E10: Sedan | F10: automatic | G10: wauffafl3en030343 | H10: ca | I10: 42 | J10: 9557 | K10: white | L10: black | M10: audi mission viejo | N10: 32100 | O10: 32250 | P10: Thu Dec 18 2014 12:00:00 GMT-0800 (PST) | Q10: {=VALUE(INDEX(_xlfn.TEXTSPLIT(P10, " "), 4))} -> 2014 | R10: =_xlfn.TEXTJOIN(" ", TRUE, B10, C10, D10) -> Audi A4 2.0T Premium Plus quattro | S10: {=_xlfn.IFS(I10 >= 40, "High", I10>=20, "Medium", I10<20, "Low")} -> High | T10: {=_xlfn.IFS(O10<18200, "Low", O10<=50000, "Medium", O10>50000, "High")} -> Medium
A11: 2014 | B11: Chevrolet | C11: Camaro | D11: LT | E11: Convertible | F11: automatic | G11: 2g1fb3d37e9218789 | H11: ca | I11: 3 | J11: 4809 | K11: red | L11: black | M11: d/m auto sales inc | N11: 26300 | O11: 17500 | P11: Tue Jan 20 2015 04:00:00 GMT-0800 (PST) | Q11: {=VALUE(INDEX(_xlfn.TEXTSPLIT(P11, " "), 4))} -> 2015 | R11: =_xlfn.TEXTJOIN(" ", TRUE, B11, C11, D11) -> Chevrolet Camaro LT | S11: {=_xlfn.IFS(I11 >= 40, "High", I11>=20, "Medium", I11<20, "Low")} -> Low | T11: {=_xlfn.IFS(O11<18200, "Low", O11<=50000, "Medium", O11>50000, "High")} -> Low
A12: 2014 | B12: Audi | C12: A6 | D12: 3.0T Prestige quattro | E12: Sedan | F12: automatic | G12: wauhgafc0en062916 | H12: ca | I12: 48 | J12: 14414 | K12: black | L12: black | M12: desert auto trade | N12: 47300 | O12: 49750 | P12: Tue Dec 16 2014 12:30:00 GMT-0800 (PST) | Q12: {=VALUE(INDEX(_xlfn.TEXTSPLIT(P12, " "), 4))} -> 2014 | R12: =_xlfn.TEXTJOIN(" ", TRUE, B12, C12, D12) -> Audi A6 3.0T Prestige quattro | S12: {=_xlfn.IFS(I12 >= 40, "High", I12>=20, "Medium", I12<20, "Low")} -> High | T12: {=_xlfn.IFS(O12<18200, "Low", O12<=50000, "Medium", O12>50000, "High")} -> Medium
A13: 2015 | B13: Kia | C13: Optima | D13: LX | E13: Sedan | F13: automatic | G13: 5xxgm4a73fg353538 | H13: ca | I13: 48 | J13: 2034 | K13: red | L13: tan | M13: kia motors finance | N13: 15150 | O13: 17700 | P13: Tue Dec 16 2014 12:00:00 GMT-0800 (PST) | Q13: {=VALUE(INDEX(_xlfn.TEXTSPLIT(P13, " "), 4))} -> 2014 | R13: =_xlfn.TEXTJOIN(" ", TRUE, B13, C13, D13) -> Kia Optima LX | S13: {=_xlfn.IFS(I13 >= 40, "High", I13>=20, "Medium", I13<20, "Low")} -> High | T13: {=_xlfn.IFS(O13<18200, "Low", O13<=50000, "Medium", O13>50000, "High")} -> Low
A14: 2015 | B14: Ford | C14: Fusion | D14: SE | E14: Sedan | F14: automatic | G14: 3fa6p0hdxfr145753 | H14: ca | I14: 2 | J14: 5559 | K14: white | L14: beige | M14: enterprise vehicle exchange / tra / rental / tulsa | N14: 15350 | O14: 12000 | P14: Tue Jan 13 2015 12:00:00 GMT-0800 (PST) | Q14: {=VALUE(INDEX(_xlfn.TEXTSPLIT(P14, " "), 4))} -> 2015 | R14: =_xlfn.TEXTJOIN(" ", TRUE, B14, C14, D14) -> Ford Fusion SE | S14: {=_xlfn.IFS(I14 >= 40, "High", I14>=20, "Medium", I14<20, "Low")} -> Low | T14: {=_xlfn.IFS(O14<18200, "Low", O14<=50000, "Medium", O14>50000, "High")} -> Low
A15: 2015 | B15: Kia | C15: Sorento | D15: LX | E15: SUV | F15: automatic | G15: 5xyktca66fg561407 | H15: ca | I15: 5 | J15: 14634 | K15: silver | L15: black | M15: kia motors america inc | N15: 20600 | O15: 21500 | P15: Tue Dec 16 2014 12:30:00 GMT-0800 (PST) | Q15: {=VALUE(INDEX(_xlfn.TEXTSPLIT(P15, " "), 4))} -> 2014 | R15: =_xlfn.TEXTJOIN(" ", TRUE, B15, C15, D15) -> Kia Sorento LX | S15: {=_xlfn.IFS(I15 >= 40, "High", I15>=20, "Medium", I15<20, "Low")} -> Low | T15: {=_xlfn.IFS(O15<18200, "Low", O15<=50000, "Medium", O15>50000, "High")} -> Medium
A16: 2014 | B16: Chevrolet | C16: Cruze | D16: 2LT | E16: Sedan | F16: automatic | G16: 1g1pe5sbxe7120097 | H16: ca | J16: 15686 | K16: blue | L16: black | M16: avis rac/san leandro | N16: 13900 | O16: 10600 | P16: Tue Dec 16 2014 12:00:00 GMT-0800 (PST) | Q16: {=VALUE(INDEX(_xlfn.TEXTSPLIT(P16, " "), 4))} -> 2014 | R16: =_xlfn.TEXTJOIN(" ", TRUE, B16, C16, D16) -> Chevrolet Cruze 2LT | S16: {=_xlfn.IFS(I16 >= 40, "High", I16>=20, "Medium", I16<20, "Low")} -> Low | T16: {=_xlfn.IFS(O16<18200, "Low", O16<=50000, "Medium", O16>50000, "High")} -> Low
A17: 2015 | B17: Nissan | C17: Altima | D17: 2.5 S | E17: Sedan | F17: automatic | G17: 1n4al3ap5fc124223 | H17: ca | I17: 2 | J17: 11398 | K17: black | L17: black | M17: enterprise vehicle exchange / tra / rental / tulsa | N17: 14750 | O17: 14100 | P17: Tue Dec 23 2014 12:00:00 GMT-0800 (PST) | Q17: {=VALUE(INDEX(_xlfn.TEXTSPLIT(P17, " "), 4))} -> 2014 | R17: =_xlfn.TEXTJOIN(" ", TRUE, B17, C17, D17) -> Nissan Altima 2.5 S | S17: {=_xlfn.IFS(I17 >= 40, "High", I17>=20, "Medium", I17<20, "Low")} -> Low | T17: {=_xlfn.IFS(O17<18200, "Low", O17<=50000, "Medium", O17>50000, "High")} -> Low
A18: 2015 | B18: Hyundai | C18: Sonata | D18: SE | E18: Sedan | F18: automatic | G18: 5npe24af4fh001562 | H18: ca | J18: 8311 | K18: red | L18: â€” | M18: avis tra | N18: 15200 | O18: 4200 | P18: Tue Dec 16 2014 13:00:00 GMT-0800 (PST) | Q18: {=VALUE(INDEX(_xlfn.TEXTSPLIT(P18, " "), 4))} -> 2014 | R18: =_xlfn.TEXTJOIN(" ", TRUE, B18, C18, D18) -> Hyundai Sonata SE | S18: {=_xlfn.IFS(I18 >= 40, "High", I18>=20, "Medium", I18<20, "Low")} -> Low | T18: {=_xlfn.IFS(O18<18200, "Low", O18<=50000, "Medium", O18>50000, "High")} -> Low
A19: 2014 | B19: Audi | C19: Q5 | D19: 2.0T Premium Plus quattro | E19: SUV | F19: automatic | G19: wa1lfafpxea085074 | H19: ca | I19: 49 | J19: 7983 | K19: white | L19: black | M19: audi north scottsdale | N19: 37100 | O19: 40000 | P19: Thu Dec 18 2014 12:30:00 GMT-0800 (PST) | Q19: {=VALUE(INDEX(_xlfn.TEXTSPLIT(P19, " "), 4))} -> 2014 | R19: =_xlfn.TEXTJOIN(" ", TRUE, B19, C19, D19) -> Audi Q5 2.0T Premium Plus quattro | S19: {=_xlfn.IFS(I19 >= 40, "High", I19>=20, "Medium", I19<20, "Low")} -> High | T19: {=_xlfn.IFS(O19<18200, "Low", O19<=50000, "Medium", O19>50000, "High")} -> Medium
A20: 2014 | B20: Chevrolet | C20: Camaro | D20: LS | E20: Coupe | F20: automatic | G20: 2g1fa1e39e9134494 | H20: ca | I20: 17 | J20: 13441 | K20: black | L20: black | M20: wells fargo dealer services | N20: 17750 | O20: 17000 | P20: Tue Dec 30 2014 15:00:00 GMT-0800 (PST) | Q20: {=VALUE(INDEX(_xlfn.TEXTSPLIT(P20, " "), 4))} -> 2014 | R20: =_xlfn.TEXTJOIN(" ", TRUE, B20, C20, D20) -> Chevrolet Camaro LS | S20: {=_xlfn.IFS(I20 >= 40, "High", I20>=20, "Medium", I20<20, "Low")} -> Low | T20: {=_xlfn.IFS(O20<18200, "Low", O20<=50000, "Medium", O20>50000, "High")} -> Low
A21: 2014 | B21: BMW | C21: 6 Series | D21: 650i | E21: Convertible | F21: automatic | G21: wbayp9c53ed169260 | H21: ca | I21: 34 | J21: 8819 | K21: black | L21: black | M21: the hertz corporation | N21: 68000 | O21: 67200 | P21: Wed Dec 17 2014 12:30:00 GMT-0800 (PST) | Q21: {=VALUE(INDEX(_xlfn.TEXTSPLIT(P21, " "), 4))} -> 2014 | R21: =_xlfn.TEXTJOIN(" ", TRUE, B21, C21, D21) -> BMW 6 Series 650i | S21: {=_xlfn.IFS(I21 >= 40, "High", I21>=20, "Medium", I21<20, "Low")} -> Medium | T21: {=_xlfn.IFS(O21<18200, "Low", O21<=50000, "Medium", O21>50000, "High")} -> High
A22: 2015 | B22: Chevrolet | C22: Impala | D22: LTZ | E22: Sedan | F22: automatic | G22: 2g1165s30f9103921 | H22: ca | I22: 19 | J22: 14538 | K22: silver | L22: black | M22: enterprise vehicle exchange / tra / rental / tulsa | N22: 24300 | O22: 7200 | P22: Tue Jul 07 2015 09:30:00 GMT-0700 (PDT) | Q22: {=VALUE(INDEX(_xlfn.TEXTSPLIT(P22, " "), 4))} -> 2015 | R22: =_xlfn.TEXTJOIN(" ", TRUE, B22, C22, D22) -> Chevrolet Impala LTZ | S22: {=_xlfn.IFS(I22 >= 40, "High", I22>=20, "Medium", I22<20, "Low")} -> Low | T22: {=_xlfn.IFS(O22<18200, "Low", O22<=50000, "Medium", O22>50000, "High")} -> Low
A23: 2014 | B23: BMW | C23: 5 Series | D23: 528i | E23: Sedan | F23: automatic | G23: wba5a5c51ed501631 | H23: ca | I23: 29 | J23: 25969 | K23: black | L23: black | M23: financial services remarketing (lease) | N23: 34200 | O23: 30000 | P23: Tue Feb 03 2015 04:30:00 GMT-0800 (PST) | Q23: {=VALUE(INDEX(_xlfn.TEXTSPLIT(P23, " "), 4))} -> 2015 | R23: =_xlfn.TEXTJOIN(" ", TRUE, B23, C23, D23) -> BMW 5 Series 528i | S23: {=_xlfn.IFS(I23 >= 40, "High", I23>=20, "Medium", I23<20, "Low")} -> Medium | T23: {=_xlfn.IFS(O23<18200, "Low", O23<=50000, "Medium", O23>50000, "High")} -> Medium
A24: 2014 | B24: Chevrolet | C24: Camaro | D24: LT | E24: Convertible | F24: automatic | G24: 2g1fb3d31e9134662 | H24: ca | J24: 33450 | K24: black | L24: black | M24: avis rac/san leandro | N24: 20100 | O24: 14700 | P24: Tue Dec 16 2014 12:00:00 GMT-0800 (PST) | Q24: {=VALUE(INDEX(_xlfn.TEXTSPLIT(P24, " "), 4))} -> 2014 | R24: =_xlfn.TEXTJOIN(" ", TRUE, B24, C24, D24) -> Chevrolet Camaro LT | S24: {=_xlfn.IFS(I24 >= 40, "High", I24>=20, "Medium", I24<20, "Low")} -> Low | T24: {=_xlfn.IFS(O24<18200, "Low", O24<=50000, "Medium", O24>50000, "High")} -> Low
A25: 2015 | B25: Audi | C25: A3 | D25: 1.8 TFSI Premium | E25: Sedan | F25: automatic | G25: wauacgff7f1002327 | H25: ca | I25: 49 | J25: 5826 | K25: gray | L25: black | M25: audi north scottsdale | N25: 24000 | O25: 23750 | P25: Thu Dec 18 2014 12:30:00 GMT-0800 (PST) | Q25: {=VALUE(INDEX(_xlfn.TEXTSPLIT(P25, " "), 4))} -> 2014 | R25: =_xlfn.TEXTJOIN(" ", TRUE, B25, C25, D25) -> Audi A3 1.8 TFSI Premium | S25: {=_xlfn.IFS(I25 >= 40, "High", I25>=20, "Medium", I25<20, "Low")} -> High | T25: {=_xlfn.IFS(O25<18200, "Low", O25<=50000, "Medium", O25>50000, "High")} -> Medium
A26: 2014 | B26: BMW | C26: 6 Series | D26: 650i | E26: Convertible | F26: automatic | G26: wbayp9c57ed169262 | H26: ca | I26: 38 | J26: 10736 | K26: black | L26: black | M26: the hertz corporation | N26: 67000 | O26: 65000 | P26: Tue Jan 06 2015 12:30:00 GMT-0800 (PST) | Q26: {=VALUE(INDEX(_xlfn.TEXTSPLIT(P26, " "), 4))} -> 2015 | R26: =_xlfn.TEXTJOIN(" ", TRUE, B26, C26, D26) -> BMW 6 Series 650i | S26: {=_xlfn.IFS(I26 >= 40, "High", I26>=20, "Medium", I26<20, "Low")} -> Medium | T26: {=_xlfn.IFS(O26<18200, "Low", O26<=50000, "Medium", O26>50000, "High")} -> High
A27: 2015 | B27: Hyundai | C27: Sonata | D27: SE | E27: Sedan | F27: automatic | G27: 5npe24af4fh038482 | H27: ca | J27: 9281 | K27: silver | L27: gray | M27: enterprise vehicle exchange / tra / rental / tulsa | N27: 15150 | O27: 8500 | P27: Tue Dec 16 2014 13:00:00 GMT-0800 (PST) | Q27: {=VALUE(INDEX(_xlfn.TEXTSPLIT(P27, " "), 4))} -> 2014 | R27: =_xlfn.TEXTJOIN(" ", TRUE, B27, C27, D27) -> Hyundai Sonata SE | S27: {=_xlfn.IFS(I27 >= 40, "High", I27>=20, "Medium", I27<20, "Low")} -> Low | T27: {=_xlfn.IFS(O27<18200, "Low", O27<=50000, "Medium", O27>50000, "High")} -> Low
A28: 2015 | B28: Volvo | C28: XC70 | D28: T6 | E28: Wagon | F28: automatic | G28: yv4902nb3f1198103 | H28: ca | I28: 42 | J28: 16506 | K28: brown | L28: brown | M28: volvo na rep/world omni | N28: 32100 | O28: 32500 | P28: Thu Feb 26 2015 04:30:00 GMT-0800 (PST) | Q28: {=VALUE(INDEX(_xlfn.TEXTSPLIT(P28, " "), 4))} -> 2015 | R28: =_xlfn.TEXTJOIN(" ", TRUE, B28, C28, D28) -> Volvo XC70 T6 | S28: {=_xlfn.IFS(I28 >= 40, "High", I28>=20, "Medium", I28<20, "Low")} -> High | T28: {=_xlfn.IFS(O28<18200, "Low", O28<=50000, "Medium", O28>50000, "High")} -> Medium
A29: 2015 | B29: Volvo | C29: XC70 | D29: T6 | E29: Wagon | F29: automatic | G29: yv4902nb3f1196951 | H29: ca | I29: 48 | J29: 12725 | K29: beige | L29: beige | M29: volvo na rep/world omni | N29: 32300 | O29: 32500 | P29: Thu Feb 12 2015 04:30:00 GMT-0800 (PST) | Q29: {=VALUE(INDEX(_xlfn.TEXTSPLIT(P29, " "), 4))} -> 2015 | R29: =_xlfn.TEXTJOIN(" ", TRUE, B29, C29, D29) -> Volvo XC70 T6 | S29: {=_xlfn.IFS(I29 >= 40, "High", I29>=20, "Medium", I29<20, "Low")} -> High | T29: {=_xlfn.IFS(O29<18200, "Low", O29<=50000, "Medium", O29>50000, "High")} -> Medium
A30: 2014 | B30: BMW | C30: X5 | D30: sDrive35i | E30: SUV | F30: automatic | G30: 5uxkr2c52e0h33130 | H30: ca | J30: 11278 | K30: gray | L30: black | M30: avis rac/san leandro | N30: 50400 | O30: 34000 | P30: Tue Dec 16 2014 13:00:00 GMT-0800 (PST) | Q30: {=VALUE(INDEX(_xlfn.TEXTSPLIT(P30, " "), 4))} -> 2014 | R30: =_xlfn.TEXTJOIN(" ", TRUE, B30, C30, D30) -> BMW X5 sDrive35i | S30: {=_xlfn.IFS(I30 >= 40, "High", I30>=20, "Medium", I30<20, "Low")} -> Low | T30: {=_xlfn.IFS(O30<18200, "Low", O30<=50000, "Medium", O30>50000, "High")} -> Medium
A31: 2014 | B31: Chevrolet | C31: Camaro | D31: LT | E31: Coupe | F31: automatic | G31: 2g1fb1e35e9238302 | H31: ca | I31: 42 | J31: 11874 | K31: gray | L31: black | M31: midway hfc fleet/ars | N31: 22200 | O31: 19500 | P31: Thu Dec 18 2014 12:00:00 GMT-0800 (PST) | Q31: {=VALUE(INDEX(_xlfn.TEXTSPLIT(P31, " "), 4))} -> 2014 | R31: =_xlfn.TEXTJOIN(" ", TRUE, B31, C31, D31) -> Chevrolet Camaro LT | S31: {=_xlfn.IFS(I31 >= 40, "High", I31>=20, "Medium", I31<20, "Low")} -> High | T31: {=_xlfn.IFS(O31<18200, "Low", O31<=50000, "Medium", O31>50000, "High")} -> Medium
A32: 2014 | B32: Chevrolet | C32: Cruze | D32: 1LT | E32: Sedan | F32: automatic | G32: 1g1pc5sb2e7105471 | H32: ca | I32: 42 | J32: 37888 | K32: gray | L32: black | M32: enterprise vehicle exchange/orange | N32: 11600 | O32: 11500 | P32: Tue Dec 30 2014 12:30:00 GMT-0800 (PST) | Q32: {=VALUE(INDEX(_xlfn.TEXTSPLIT(P32, " "), 4))} -> 2014 | R32: =_xlfn.TEXTJOIN(" ", TRUE, B32, C32, D32) -> Chevrolet Cruze 1LT | S32: {=_xlfn.IFS(I32 >= 40, "High", I32>=20, "Medium", I32<20, "Low")} -> High | T32: {=_xlfn.IFS(O32<18200, "Low", O32<=50000, "Medium", O32>50000, "High")} -> Low
A33: 2014 | B33: Audi | C33: SQ5 | D33: 3.0T Premium Plus quattro | E33: SUV | F33: automatic | G33: wa1cgafp4ea030312 | H33: ca | I33: 42 | J33: 9606 | K33: white | L33: black | M33: audi of downtown l a | N33: 48600 | O33: 47500 | P33: Thu Jan 29 2015 04:00:00 GMT-0800 (PST) | Q33: {=VALUE(INDEX(_xlfn.TEXTSPLIT(P33, " "), 4))} -> 2015 | R33: =_xlfn.TEXTJOIN(" ", TRUE, B33, C33, D33) -> Audi SQ5 3.0T Premium Plus quattro | S33: {=_xlfn.IFS(I33 >= 40, "High", I33>=20, "Medium", I33<20, "Low")} -> High | T33: {=_xlfn.IFS(O33<18200, "Low", O33<=50000, "Medium", O33>50000, "High")} -> Medium
A34: 2015 | B34: Kia | C34: Sorento | D34: LX | E34: SUV | F34: automatic | G34: 5xyktca60fg565226 | H34: ca | I34: 5 | J34: 13757 | K34: red | L34: black | M34: kia motors america inc | N34: 20600 | O34: 20750 | P34: Tue Dec 16 2014 12:30:00 GMT-0800 (PST) | Q34: {=VALUE(INDEX(_xlfn.TEXTSPLIT(P34, " "), 4))} -> 2014 | R34: =_xlfn.TEXTJOIN(" ", TRUE, B34, C34, D34) -> Kia Sorento LX | S34: {=_xlfn.IFS(I34 >= 40, "High", I34>=20, "Medium", I34<20, "Low")} -> Low | T34: {=_xlfn.IFS(O34<18200, "Low", O34<=50000, "Medium", O34>50000, "High")} -> Medium
A35: 2014 | B35: Audi | C35: S5 | D35: Premium Plus quattro | E35: Coupe | F35: automatic | G35: waucgafrxea001689 | H35: ca | I35: 38 | J35: 5875 | K35: black | L35: black | M35: fratelli investment group | N35: 46500 | O35: 44500 | P35: Thu Dec 18 2014 12:00:00 GMT-0800 (PST) | Q35: {=VALUE(INDEX(_xlfn.TEXTSPLIT(P35, " "), 4))} -> 2014 | R35: =_xlfn.TEXTJOIN(" ", TRUE, B35, C35, D35) -> Audi S5 Premium Plus quattro | S35: {=_xlfn.IFS(I35 >= 40, "High", I35>=20, "Medium", I35<20, "Low")} -> Medium | T35: {=_xlfn.IFS(O35<18200, "Low", O35<=50000, "Medium", O35>50000, "High")} -> Medium
A36: 2015 | B36: Kia | C36: Sorento | D36: LX | E36: SUV | F36: automatic | G36: 5xyktca68fg559481 | H36: ca | I36: 44 | J36: 12862 | K36: gray | L36: black | M36: kia motors america inc | N36: 20700 | O36: 21000 | P36: Tue Dec 16 2014 12:30:00 GMT-0800 (PST) | Q36: {=VALUE(INDEX(_xlfn.TEXTSPLIT(P36, " "), 4))} -> 2014 | R36: =_xlfn.TEXTJOIN(" ", TRUE, B36, C36, D36) -> Kia Sorento LX | S36: {=_xlfn.IFS(I36 >= 40, "High", I36>=20, "Medium", I36<20, "Low")} -> High | T36: {=_xlfn.IFS(O36<18200, "Low", O36<=50000, "Medium", O36>50000, "High")} -> Medium
A37: 2014 | B37: Buick | C37: Verano | D37: Convenience Group | E37: Sedan | G37: 1g4pr5sk8e4175320 | H37: ca | I37: 2 | J37: 19531 | K37: gray | L37: gray | M37: enterprise vehicle exchange / tra / rental / tulsa | N37: 15000 | O37: 9200 | P37: Tue Jan 06 2015 04:00:00 GMT-0800 (PST) | Q37: {=VALUE(INDEX(_xlfn.TEXTSPLIT(P37, " "), 4))} -> 2015 | R37: =_xlfn.TEXTJOIN(" ", TRUE, B37, C37, D37) -> Buick Verano Convenience Group | S37: {=_xlfn.IFS(I37 >= 40, "High", I37>=20, "Medium", I37<20, "Low")} -> Low | T37: {=_xlfn.IFS(O37<18200, "Low", O37<=50000, "Medium", O37>50000, "High")} -> Low
A38: 2015 | B38: Chevrolet | C38: Suburban | D38: LTZ | E38: SUV | F38: automatic | G38: 1gnskkkc3fr187901 | H38: ca | I38: 45 | J38: 11426 | K38: black | L38: black | M38: midway hfc fleet/ars | N38: 57300 | O38: 59900 | P38: Thu Dec 18 2014 12:00:00 GMT-0800 (PST) | Q38: {=VALUE(INDEX(_xlfn.TEXTSPLIT(P38, " "), 4))} -> 2014 | R38: =_xlfn.TEXTJOIN(" ", TRUE, B38, C38, D38) -> Chevrolet Suburban LTZ | S38: {=_xlfn.IFS(I38 >= 40, "High", I38>=20, "Medium", I38<20, "Low")} -> High | T38: {=_xlfn.IFS(O38<18200, "Low", O38<=50000, "Medium", O38>50000, "High")} -> High
A39: 2014 | B39: BMW | C39: 3 Series | D39: 328i SULEV | E39: Sedan | F39: automatic | G39: wba3c1c50ek108497 | H39: ca | I39: 5 | J39: 111 | K39: black | L39: â€” | M39: financial services remarketing (lease) | N39: 32200 | O39: 30500 | P39: Thu Jan 15 2015 04:30:00 GMT-0800 (PST) | Q39: {=VALUE(INDEX(_xlfn.TEXTSPLIT(P39, " "), 4))} -> 2015 | R39: =_xlfn.TEXTJOIN(" ", TRUE, B39, C39, D39) -> BMW 3 Series 328i SULEV | S39: {=_xlfn.IFS(I39 >= 40, "High", I39>=20, "Medium", I39<20, "Low")} -> Low | T39: {=_xlfn.IFS(O39<18200, "Low", O39<=50000, "Medium", O39>50000, "High")} -> Medium
A40: 2014 | B40: BMW | C40: M5 | D40: Base | E40: Sedan | F40: automatic | G40: wbsfv9c56ed593069 | H40: ca | I40: 38 | J40: 16360 | K40: black | L40: black | M40: the hertz corporation | N40: 65000 | O40: 64250 | P40: Tue Jan 13 2015 04:30:00 GMT-0800 (PST) | Q40: {=VALUE(INDEX(_xlfn.TEXTSPLIT(P40, " "), 4))} -> 2015 | R40: =_xlfn.TEXTJOIN(" ", TRUE, B40, C40, D40) -> BMW M5 Base | S40: {=_xlfn.IFS(I40 >= 40, "High", I40>=20, "Medium", I40<20, "Low")} -> Medium | T40: {=_xlfn.IFS(O40<18200, "Low", O40<=50000, "Medium", O40>50000, "High")} -> High
...

Sheet Price_vs_odometer
B3: Column Labels
B4: High | C4: Low | D4: Medium | E4: Grand Total
A5: Count of car_full_name | B5: 771 | C5: 342 | D5: 886 | E5: 1999
B10: Column Labels
B11: High | C11: Low | D11: Medium | E11: Grand Total
A12: Count of price_flag | B12: 771 | C12: 342 | D12: 886 | E12: 1999
